Workbook

Sheet Master Summary
A1: HSSC CLASS 12th (ANNUAL-I) — MASTER SUMMARY — ALL BISE BOARDS — 2024-2026
A2: Boards: Abbottabad, Bahawalpur, Bannu, D.G. Khan, Faisalabad, FBISE, Gujranwala, Kohat, Lahore, Mardan, Peshawar, Rawalpindi, Sahiwal, Sargodha, Swat. Figures are each board's Class 12th final-year grand total (where a board reports Part-I and Part-II or Class 11th and 12th separately, the Part-II / 12th-only row is used for comparability). Pass % is recomputed live as Passed ÷ Appeared for every board; the overall figure printed in the gazette (where there is one) is kept in 'Published Pass %' for audit.
A4: Board | B4: Year | C4: Appeared | D4: Passed | E4: Pass % | F4: Notes | G4: Published Pass %
A5: Abbottabad | B5: 2024 | C5: ='Abb-Overall Summary'!B5 -> 39267 | D5: ='Abb-Overall Summary'!C5 -> 33644 | E5: =ROUND(D5/C5*100,2) -> 85.68 | F5: Appeared includes 396 absent | G5: 86.55
A6: Abbottabad | B6: 2025 | C6: ='Abb-Overall Summary'!B6 -> 42357 | D6: ='Abb-Overall Summary'!C6 -> 36550 | E6: =ROUND(D6/C6*100,2) -> 86.29 | F6: Appeared includes 416 absent | G6: 87.15
A7: Abbottabad | B7: 2026 | C7: ='Abb-Overall Summary'!B7 -> 45757 | D7: ='Abb-Overall Summary'!C7 -> 35818 | E7: =ROUND(D7/C7*100,2) -> 78.28 | F7: Appeared includes 480 absent | G7: 79.11
A8: Bahawalpur | B8: 2024 | C8: ='BWP Year-over-Year Summary'!H5 -> 57660 | D8: ='BWP Year-over-Year Summary'!I5 -> 34689 | E8: =ROUND(D8/C8*100,2) -> 60.16 | F8: Part I & II combined; Appeared excludes 948 absent/cancelled roll nos. | G8: 60.16
A9: Bahawalpur | B9: 2025 | C9: ='BWP Year-over-Year Summary'!H6 -> 55727 | D9: ='BWP Year-over-Year Summary'!I6 -> 35404 | E9: =ROUND(D9/C9*100,2) -> 63.53 | F9: Part I & II combined; Appeared excludes absent/cancelled roll nos. (2025 counts not in supplied pages) | G9: 63.53
A10: Bahawalpur | B10: 2026 | C10: ='BWP Year-over-Year Summary'!H7 -> 60592 | D10: ='BWP Year-over-Year Summary'!I7 -> 36304 | E10: =ROUND(D10/C10*100,2) -> 59.92 | F10: Part I & II combined; Appeared excludes 1,076 absent/cancelled roll nos.; 61,668 applied | G10: 59.92
A11: Bannu | B11: 2025 | C11: ='BNU Overall Summary'!C6 -> 18099 | D11: ='BNU Overall Summary'!D6 -> 15484 | E11: =ROUND(D11/C11*100,2) -> 85.55 | F11: Part-II (final, 2nd Year); Part-I: 16,859 promoted (16,604 passed, 98%); group Appeared adds to 18,056 vs printed 18,099 - Sub Total used; published % is a whole number | G11: 86
A12: Bannu | B12: 2026 | C12: ='BNU Overall Summary'!C9 -> 17771 | D12: ='BNU Overall Summary'!D9 -> 14484 | E12: =ROUND(D12/C12*100,2) -> 81.5 | F12: Part-II (final, 2nd Year); Part-I: 17,857 appeared, 14,845 passed (83%); gazette Private-category Passed counts are below their grade counts - printed totals used; published % is a whole number | G12: 82
A13: D.G. Khan | B13: 2024 | C13: ='DGK-Overall Summary'!C5 -> 60102 | D13: ='DGK-Overall Summary'!D5 -> 42341 | E13: =ROUND(D13/C13*100,2) -> 70.45 | F13: Part-II & Combined; 60,539 applied | G13: 70.45
A14: D.G. Khan | B14: 2025 | C14: ='DGK-Overall Summary'!C6 -> 56083 | D14: ='DGK-Overall Summary'!D6 -> 41985 | E14: =ROUND(D14/C14*100,2) -> 74.86 | F14: Part-II & Combined; 56,655 applied | G14: 74.86
A15: D.G. Khan | B15: 2026 | C15: ='DGK-Overall Summary'!C7 -> 59243 | D15: ='DGK-Overall Summary'!D7 -> 43332 | E15: =ROUND(D15/C15*100,2) -> 73.14 | F15: Part-II & Combined; 59,629 applied | G15: 73.14
A16: Faisalabad | B16: 2024 | C16: ='FSD Overall Summary'!C4 -> 103269 | D16: ='FSD Overall Summary'!D4 -> 74154 | E16: =ROUND(D16/C16*100,2) -> 71.81 | F16: Regular + Private; gazette gives Regular 79.00% and Private 47.79% only (no overall %)
A17: Faisalabad | B17: 2025 | C17: ='FSD Overall Summary'!C7 -> 104009 | D17: ='FSD Overall Summary'!D7 -> 76661 | E17: =ROUND(D17/C17*100,2) -> 73.71 | F17: Regular + Private (105,433 admission forms submitted); Regular 80.30%, Private 50.16% | G17: 73.71
A18: Faisalabad | B18: 2026 | C18: ='FSD Overall Summary'!C10 -> 109244 | D18: ='FSD Overall Summary'!D10 -> 77708 | E18: =ROUND(D18/C18*100,2) -> 71.13 | F18: Regular + Private; Regular 78.29%, Private 43.32%; applied/admission-form count not on supplied pages | G18: 71.13
A19: FBISE | B19: 2024 | C19: ='FBISE Summary'!E2 -> 89261 | D19: ='FBISE Summary'!G2 -> 72653 | E19: =ROUND(D19/C19*100,2) -> 81.39 | F19: HSSC-II, All Areas (Regular + Private); enrolled 90,518, absent 1,257; published % is on Appeared less RL | G19: 82.58
A20: FBISE | B20: 2025 | C20: ='FBISE Summary'!E11 -> 96521 | D20: ='FBISE Summary'!G11 -> 79881 | E20: =ROUND(D20/C20*100,2) -> 82.76 | F20: HSSC-II, All Areas (Regular + Private); enrolled 97,925, absent 1,404; published % is on Appeared less RL | G20: 83.19
A21: FBISE | B21: 2026 | C21: ='FBISE Summary'!E20 -> 103178 | D21: ='FBISE Summary'!G20 -> 87364 | E21: =ROUND(D21/C21*100,2) -> 84.67 | F21: HSSC-II, All Areas (Regular + Private); enrolled 104,838, absent 1,660; published % is on Appeared less RL | G21: 85.95
A22: Gujranwala | B22: 2024 | C22: ='GRW Year-over-Year Summary'!B5 -> 142834 | D22: ='GRW Year-over-Year Summary'!C5 -> 89019 | E22: =ROUND(D22/C22*100,2) -> 62.32 | F22: Part-II First Annual; overall % not stated in gazette; no applied count given
A23: Gujranwala | B23: 2025 | C23: ='GRW Year-over-Year Summary'!B6 -> 135810 | D23: ='GRW Year-over-Year Summary'!C6 -> 85696 | E23: =ROUND(D23/C23*100,2) -> 63.1 | F23: Part-II First Annual; overall % not stated in gazette; no applied count given
A24: Kohat | B24: 2025 | C24: ='KOH Overall Summary'!C6 -> 29496 | D24: ='KOH Overall Summary'!D6 -> 16808 | E24: =ROUND(D24/C24*100,2) -> 56.98 | F24: Part-II (final, 2nd Year); Part-I: 34,012 appeared, 10,899 passed (32.04%); group Appeared adds to 29,495 vs printed 29,496 - printed total used | G24: 56.98
A25: Kohat | B25: 2026 | C25: ='KOH Overall Summary'!C9 -> 31496 | D25: ='KOH Overall Summary'!D9 -> 9724 | E25: =ROUND(D25/C25*100,2) -> 30.87 | F25: Part-II (final, 2nd Year); Part-I: 22,728 appeared, 6,138 passed (27.01%); group Appeared adds to 31,496 only via printed group totals (two groups each 1 above the sum of their categories) | G25: 30.87
A26: Lahore | B26: 2024 | C26: ='LHR Year-over-Year Summary'!C5 -> 190218 | D26: ='LHR Year-over-Year Summary'!D5 -> 114985 | E26: =ROUND(D26/C26*100,2) -> 60.45 | F26: Part I & II combined; 194,766 applied | G26: 60.45
A27: Lahore | B27: 2025 | C27: ='LHR Year-over-Year Summary'!C6 -> 180329 | D27: ='LHR Year-over-Year Summary'!D6 -> 109741 | E27: =ROUND(D27/C27*100,2) -> 60.86 | F27: Part I & II combined; 184,000 applied | G27: 60.86
A28: Lahore | B28: 2026 | C28: ='LHR Year-over-Year Summary'!C7 -> 189373 | D28: ='LHR Year-over-Year Summary'!D7 -> 123060 | E28: =ROUND(D28/C28*100,2) -> 64.98 | F28: Part I & II combined; 192,950 applied; Appeared/Passed include 431 / 223 Additional-subject candidates not in the group rows | G28: 64.98
A29: Mardan | B29: 2024 | C29: ='Mar-Overview'!B5 -> 42873 | D29: ='Mar-Overview'!C5 -> 40105 | E29: =ROUND(D29/C29*100,2) -> 93.54 | F29: Annual-I Part-II; no grade data in gazette | G29: 93.54
A30: Mardan | B30: 2025 | C30: ='Mar-Overview'!B6 -> 45778 | D30: ='Mar-Overview'!C6 -> 38674 | E30: =ROUND(D30/C30*100,2) -> 84.48 | F30: Annual-I Part-II; no grade data in gazette | G30: 84.48
A31: Mardan | B31: 2026 | C31: ='Mar-Overview'!B7 -> 49250 | D31: ='Mar-Overview'!C7 -> 39178 | E31: =ROUND(D31/C31*100,2) -> 79.55 | F31: Annual-I Part-II; no grade data in gazette | G31: 79.55
A32: Peshawar | B32: 2024 | C32: ='Pes-Summary (2024-2026)'!C6 -> 61217 | D32: ='Pes-Summary (2024-2026)'!D6 -> 56117 | E32: =ROUND(D32/C32*100,2) -> 91.67 | F32: Annual-I Part-II (final result); 497 absent included in Appeared; Part-I: 62,886 students, 50,207 passed, 99.1% (promotion-based); published % is a whole number | G32: 92
A33: Peshawar | B33: 2025 | C33: ='Pes-Summary (2024-2026)'!C7 -> 62322 | D33: ='Pes-Summary (2024-2026)'!D7 -> 44902 | E33: =ROUND(D33/C33*100,2) -> 72.05 | F33: Annual-I Part-II (final result); 583 absent included in Appeared; no Part-I result in the 2025 gazette; published % is a whole number | G33: 72
A34: Peshawar | B34: 2026 | C34: ='Pes-Summary (2024-2026)'!C9 -> 66735 | D34: ='Pes-Summary (2024-2026)'!D9 -> 35103 | E34: =ROUND(D34/C34*100,2) -> 52.6 | F34: Annual-I Part-II (final result); 754 absent included in Appeared; Part-I: 63,605 students, 31,169 passed, 31,864 promoted, 99.10% (promotion-based) | G34: 52.6
A35: Rawalpindi | B35: 2024 | C35: ='RWP Overview Summary'!E2 -> 63291 | D35: ='RWP Overview Summary'!F2 -> 35922 | E35: =ROUND(D35/C35*100,2) -> 56.76 | F35: 1st Annual; 64,232 enrolled; Appeared excludes 917 absent and 24 cancelled | G35: 56.76
A36: Rawalpindi | B36: 2025 | C36: ='RWP Overview Summary'!E3 -> 58940 | D36: ='RWP Overview Summary'!F3 -> 31898 | E36: =ROUND(D36/C36*100,2) -> 54.12 | F36: 1st Annual; 59,784 enrolled; Appeared excludes 813 absent and 31 cancelled | G36: 54.12
A37: Rawalpindi | B37: 2026 | C37: ='RWP Overview Summary'!E4 -> 61409 | D37: ='RWP Overview Summary'!F4 -> 36896 | E37: =ROUND(D37/C37*100,2) -> 60.08 | F37: 1st Annual; 62,233 enrolled; Appeared excludes 795 absent and 29 cancelled | G37: 60.08
A38: Sahiwal | B38: 2024 | C38: ='SWL Result At a Glance'!C5 -> 45519 | D38: ='SWL Result At a Glance'!D5 -> 25177 | E38: =ROUND(D38/C38*100,2) -> 55.31 | F38: Part-II First Annual; 46,877 applied | G38: 55.31
A39: Sahiwal | B39: 2025 | C39: ='SWL Result At a Glance'!C6 -> 43241 | D39: ='SWL Result At a Glance'!D6 -> 25478 | E39: =ROUND(D39/C39*100,2) -> 58.92 | F39: Part-II First Annual; 44,302 applied | G39: 58.92
A40: Sahiwal | B40: 2026 | C40: ='SWL Result At a Glance'!C7 -> 46248 | D40: ='SWL Result At a Glance'!D7 -> 28868 | E40: =ROUND(D40/C40*100,2) -> 62.42 | F40: Part-II First Annual; 47,353 applied | G40: 62.42
A41: Sargodha | B41: 2024 | C41: ='Sar-Overall Summary'!C5 -> 52457 | D41: ='Sar-Overall Summary'!D5 -> 35656 | E41: =ROUND(D41/C41*100,2) -> 67.97 | F41: Part-II (Composite) First Annual; 53,507 applied; 1,050 absent and 2,080 cancelled excluded from Appeared | G41: 67.97
...

Sheet Abb-Overall Summary
A1: BOARD OF INTERMEDIATE & SECONDARY EDUCATION ABBOTTABAD
A2: HSSC Class 12th (Annual-I) — Result at a Glance — 2024, 2025 and 2026. "Appeared" includes Absent candidates (Pass % is published as Passed ÷ (Appeared − Absent)).
A4: Year | B4: Appeared | C4: Passed | D4: Failed/Absent | E4: Pass % | F4: Absent
A5: 2024 | B5: 39267 | C5: 33644 | D5: =B5-C5 -> 5623 | E5: 0.8655 | F5: 396
A6: 2025 | B6: 42357 | C6: 36550 | D6: =B6-C6 -> 5807 | E6: 0.8715 | F6: 416
A7: 2026 | B7: 45757 | C7: 35818 | D7: =B7-C7 -> 9939 | E7: 0.7911 | F7: 480

Sheet Abb-Group-wise
A1: Group-Wise Pass Percentage & Grade Distribution — HSSC Class 12th (2024–2026)
A2: Source: BISE Abbottabad Result at a Glance, HSSC 2024, 2025 and 2026 gazettes. Failed/Absent = Appeared − Passed. Pass % as published.
A4: Year | B4: Candidate Type | C4: Gender | D4: Group | E4: Appeared | F4: Passed | G4: Failed/Absent | H4: Pass % | I4: A1 | J4: A | K4: B | L4: C | M4: D | N4: E | O4: Absent
A5: 2024 | B5: Regular | C5: Female | D5: Pre-Medical | E5: 6980 | F5: 6254 | G5: =E5-F5 -> 726 | H5: 0.8992 | I5: 1211 | J5: 1788 | K5: 2207 | L5: 997 | M5: 51 | N5: 0 | O5: 25
A6: 2024 | B6: Regular | C6: Male | D6: Pre-Medical | E6: 9376 | F6: 8338 | G6: =E6-F6 -> 1038 | H6: 0.9007 | I6: 1011 | J6: 2024 | K6: 2516 | L6: 2221 | M6: 565 | N6: 1 | O6: 119
A7: 2024 | B7: Private | C7: Female | D7: Pre-Medical | E7: 785 | F7: 587 | G7: =E7-F7 -> 198 | H7: 0.7673 | I7: 252 | J7: 82 | K7: 80 | L7: 126 | M7: 46 | N7: 1 | O7: 20
A8: 2024 | B8: Private | C8: Male | D8: Pre-Medical | E8: 1058 | F8: 807 | G8: =E8-F8 -> 251 | H8: 0.7889 | I8: 272 | J8: 112 | K8: 125 | L8: 171 | M8: 122 | N8: 5 | O8: 35
A9: 2024 | B9: Regular | C9: Female | D9: Pre-Engineering | E9: 720 | F9: 590 | G9: =E9-F9 -> 130 | H9: 0.8229 | I9: 137 | J9: 163 | K9: 164 | L9: 113 | M9: 13 | N9: 0 | O9: 3
A10: 2024 | B10: Regular | C10: Male | D10: Pre-Engineering | E10: 2852 | F10: 2489 | G10: =E10-F10 -> 363 | H10: 0.8786 | I10: 219 | J10: 563 | K10: 604 | L10: 798 | M10: 304 | N10: 1 | O10: 19
A11: 2024 | B11: Private | C11: Female | D11: Pre-Engineering | E11: 62 | F11: 42 | G11: =E11-F11 -> 20 | H11: 0.6885 | I11: 0 | J11: 3 | K11: 4 | L11: 24 | M11: 10 | N11: 1 | O11: 1
A12: 2024 | B12: Private | C12: Male | D12: Pre-Engineering | E12: 251 | F12: 177 | G12: =E12-F12 -> 74 | H12: 0.7284 | I12: 4 | J12: 10 | K12: 30 | L12: 59 | M12: 66 | N12: 8 | O12: 8
A13: 2024 | B13: Regular | C13: Female | D13: Computer / General Science | E13: 1396 | F13: 1219 | G13: =E13-F13 -> 177 | H13: 0.8751 | I13: 123 | J13: 330 | K13: 441 | L13: 293 | M13: 32 | N13: 0 | O13: 3
A14: 2024 | B14: Regular | C14: Male | D14: Computer / General Science | E14: 3686 | F14: 3318 | G14: =E14-F14 -> 368 | H14: 0.908 | I14: 86 | J14: 559 | K14: 1052 | L14: 1228 | M14: 393 | N14: 0 | O14: 32
A15: 2024 | B15: Private | C15: Female | D15: Computer / General Science | E15: 97 | F15: 59 | G15: =E15-F15 -> 38 | H15: 0.6082 | I15: 0 | J15: 4 | K15: 9 | L15: 22 | M15: 22 | N15: 2 | O15: 0
A16: 2024 | B16: Private | C16: Male | D16: Computer / General Science | E16: 171 | F16: 127 | G16: =E16-F16 -> 44 | H16: 0.7697 | I16: 1 | J16: 8 | K16: 27 | L16: 36 | M16: 50 | N16: 5 | O16: 6
... A58: 2026 | B58: Private | C58: Female | D58: Home Economics | E58: 4 | F58: 4 | G58: =E58-F58 -> 0 | H58: 1 | I58: 0 | J58: 0 | K58: 0 | L58: 3 | M58: 1 | N58: 0 | O58: 0

Sheet Abb-Overall by Type-Gender
A1: Overall Pass Percentage — by Candidate Type & Gender — HSSC Class 12th (2024–2026)
A2: Source: BISE Abbottabad Result at a Glance, HSSC 2024, 2025 and 2026 gazettes.
A4: Year | B4: Candidate Type | C4: Appeared | D4: Passed | E4: Failed/Absent | F4: Pass % | G4: Absent
A5: 2024 | B5: Regular Female | C5: 12796 | D5: 11373 | E5: =C5-D5 -> 1423 | F5: 0.8919 | G5: 44
A6: 2024 | B6: Regular Male | C6: 18131 | D6: 16074 | E6: =C6-D6 -> 2057 | F6: 0.8957 | G6: 185
A7: 2024 | B7: Private Female | C7: 3605 | D7: 2523 | E7: =C7-D7 -> 1082 | F7: 0.7105 | G7: 54
A8: 2024 | B8: Private Male | C8: 4735 | D8: 3674 | E8: =C8-D8 -> 1061 | F8: 0.7949 | G8: 113
A9: 2024 | B9: Grand Total | C9: 39267 | D9: 33644 | E9: =C9-D9 -> 5623 | F9: 0.8655 | G9: 396
A10: 2025 | B10: Regular Female | C10: 15534 | D10: 14050 | E10: =C10-D10 -> 1484 | F10: 0.9078 | G10: 57
A11: 2025 | B11: Regular Male | C11: 19278 | D11: 17192 | E11: =C11-D11 -> 2086 | F11: 0.8994 | G11: 164
A12: 2025 | B12: Private Female | C12: 3381 | D12: 2362 | E12: =C12-D12 -> 1019 | F12: 0.7087 | G12: 48
A13: 2025 | B13: Private Male | C13: 4164 | D13: 2946 | E13: =C13-D13 -> 1218 | F13: 0.7334 | G13: 147
A14: 2025 | B14: Grand Total | C14: 42357 | D14: 36550 | E14: =C14-D14 -> 5807 | F14: 0.8715 | G14: 416
A15: 2026 | B15: Regular Female | C15: 17403 | D15: 14979 | E15: =C15-D15 -> 2424 | F15: 0.8636 | G15: 59
A16: 2026 | B16: Regular Male | C16: 21493 | D16: 15909 | E16: =C16-D16 -> 5584 | F16: 0.7484 | G16: 235
... A19: 2026 | B19: Grand Total | C19: 45757 | D19: 35818 | E19: =C19-D19 -> 9939 | F19: 0.7911 | G19: 480

Sheet Abb-Additional-Qualifying
A1: Additional / Qualifying Subjects Pass Percentage — HSSC Class 12th (2024–2026)
A2: Source: BISE Abbottabad Result at a Glance, HSSC 2024, 2025 and 2026 gazettes.
A4: Year | B4: Candidate Type | C4: Appeared | D4: Passed | E4: Failed/Absent | F4: Pass % | G4: Absent
A5: 2024 | B5: Private Female | C5: 110 | D5: 71 | E5: =C5-D5 -> 39 | F5: 0.6698 | G5: 4
A6: 2024 | B6: Private Male | C6: 323 | D6: 253 | E6: =C6-D6 -> 70 | F6: 0.8241 | G6: 16
A7: 2025 | B7: Private Female | C7: 94 | D7: 67 | E7: =C7-D7 -> 27 | F7: 0.7283 | G7: 2
A8: 2025 | B8: Private Male | C8: 211 | D8: 170 | E8: =C8-D8 -> 41 | F8: 0.8543 | G8: 12
A9: 2026 | B9: Private Female | C9: 83 | D9: 71 | E9: =C9-D9 -> 12 | F9: 0.8659 | G9: 1
A10: 2026 | B10: Private Male | C10: 165 | D10: 121 | E10: =C10-D10 -> 44 | F10: 0.7658 | G10: 7

Sheet Abb-Subject-wise
A1: Subject-Wise Pass Percentage — HSSC Class 12th (2024–2025)
A2: Source: BISE Abbottabad Result at a Glance, HSSC 2024 and 2025 gazettes (subject-wise page). Pass % as published. 2026 subject-wise page not yet supplied.
A4: Year | B4: Subject | C4: Appeared | D4: Passed | E4: Pass %
A5: 2024 | B5: English | C5: 36796 | D5: 35053 | E5: 0.9526
A6: 2024 | B6: Ethics | C6: 3 | D6: 3 | E6: 1
A7: 2024 | B7: Urdu (Comp) | C7: 36442 | D7: 35376 | E7: 0.9707
A8: 2024 | B8: Pakistani Culture | C8: 7 | D8: 7 | E8: 1
A9: 2024 | B9: Clothing & Related Arts | C9: 7 | D9: 7 | E9: 1
A10: 2024 | B10: Home Managment | C10: 7 | D10: 7 | E10: 1
A11: 2024 | B11: Food And Nutrition | C11: 7 | D11: 7 | E11: 1
A12: 2024 | B12: Pakistan Studies | C12: 36399 | D12: 35852 | E12: 0.985
A13: 2024 | B13: Education | C13: 684 | D13: 634 | E13: 0.9269
A14: 2024 | B14: Islamic History | C14: 6537 | D14: 6319 | E14: 0.9667
A15: 2024 | B15: Economics | C15: 1755 | D15: 1693 | E15: 0.9647
A16: 2024 | B16: Psychology | C16: 374 | D16: 370 | E16: 0.9893
... A67: 2025 | B67: Urdu (Advance) | C67: 1032 | D67: 974 | E67: 0.9438

Sheet BWP Year-over-Year Summary
A1: BISE Bahawalpur — HSSC First Annual (Part I & II Combined): Year-over-Year Summary (2024-2026)
A2: 2024, 2025 and 2026 gazettes supplied. Appeared excludes absent/cancelled roll numbers (2026: 61,668 applied, 1,076 absent/cancelled; 2025 absent/applied counts not on the supplied pages).
A4: Year | B4: Regular Appeared | C4: Regular Passed | D4: Regular Pass % | E4: Private Appeared | F4: Private Passed | G4: Private Pass % | H4: Total Appeared | I4: Total Passed | J4: Overall Pass %
A5: 2024 | B5: 44022 | C5: 29597 | D5: 67.23 | E5: 13638 | F5: 5092 | G5: 37.34 | H5: 57660 | I5: 34689 | J5: 60.16
A6: 2025 | B6: 43591 | C6: 30230 | D6: 69.35 | E6: 12136 | F6: 5174 | G6: 42.63 | H6: 55727 | I6: 35404 | J6: 63.53
A7: 2026 | B7: 48249 | C7: 31850 | D7: 66.01 | E7: 12343 | F7: 4454 | G7: 36.09 | H7: 60592 | I7: 36304 | J7: 59.92

Sheet BWP 2024 Result at a Glance
A1: BOARD OF INTERMEDIATE AND SECONDARY EDUCATION BAHAWALPUR — Result at a Glance, Intermediate Part I & II Combined (First Annual) 2024
A2: Item E in the gazette is labelled "Total number of candidates who appeared" but the values (67.23 / 37.34 / 60.16) are pass percentages, so it is labelled "Pass percentage" here.
A4: Item | B4: Category | C4: Value
A5: Total number of candidates who applied for admission | C5: 58608
A6: Total number of absent candidates & Cancelled Roll No | C6: 948
A7: Total number of candidates who appeared | B7: Regular | C7: 44022
A8: Total number of candidates who appeared | B8: Private | C8: 13638
A9: Total number of candidates who appeared | B9: Total | C9: 57660
A10: Number of successful candidates | B10: Regular | C10: 29597
A11: Number of successful candidates | B11: Private | C11: 5092
A12: Number of successful candidates | B12: Total | C12: 34689
A13: Pass percentage | B13: Regular | C13: 67.23
A14: Pass percentage | B14: Private | C14: 37.34
A15: Pass percentage | B15: Overall | C15: 60.16

Sheet BWP 2024 Regular (Govt.)
A1: BISE Bahawalpur — General Pass Percentage — Regular (Govt.) — Intermediate Part I & II Combined (First Annual) 2024
A2: Source: BISE Bahawalpur Result at a Glance, Intermediate Part I & II Combined (First Annual) 2024 gazette. Pass % as published.
A4: Group | B4: Gender | C4: Appeared | D4: Pass | E4: Pass % | F4: A+ | G4: A | H4: B | I4: C | J4: D | K4: E
A5: Pre Medical | B5: Male | C5: 1430 | D5: 1109 | E5: 77.55 | F5: 209 | G5: 240 | H5: 343 | I5: 283 | J5: 34 | K5: 0
A6: Pre Medical | B6: Female | C6: 3453 | D6: 2821 | E6: 81.7 | F6: 394 | G6: 645 | H6: 1065 | I6: 679 | J6: 38 | K6: 0
A7: Pre Medical | B7: Total | C7: 4883 | D7: 3930 | E7: 80.48 | F7: 603 | G7: 885 | H7: 1408 | I7: 962 | J7: 72 | K7: 0
A8: Pre Engineering | B8: Male | C8: 471 | D8: 330 | E8: 70.06 | F8: 35 | G8: 62 | H8: 108 | I8: 105 | J8: 20 | K8: 0
A9: Pre Engineering | B9: Female | C9: 356 | D9: 285 | E9: 80.06 | F9: 27 | G9: 57 | H9: 108 | I9: 84 | J9: 9 | K9: 0
A10: Pre Engineering | B10: Total | C10: 827 | D10: 615 | E10: 74.37 | F10: 62 | G10: 119 | H10: 216 | I10: 189 | J10: 29 | K10: 0
A11: General Science | B11: Male | C11: 2262 | D11: 1005 | E11: 44.43 | F11: 24 | G11: 134 | H11: 319 | I11: 433 | J11: 95 | K11: 0
A12: General Science | B12: Female | C12: 2506 | D12: 1493 | E12: 59.58 | F12: 54 | G12: 212 | H12: 566 | I12: 600 | J12: 61 | K12: 0
A13: General Science | B13: Total | C13: 4768 | D13: 2498 | E13: 52.39 | F13: 78 | G13: 346 | H13: 885 | I13: 1033 | J13: 156 | K13: 0
A14: Humanities | B14: Male | C14: 3924 | D14: 1386 | E14: 35.32 | F14: 23 | G14: 185 | H14: 554 | I14: 510 | J14: 113 | K14: 1
A15: Humanities | B15: Female | C15: 6310 | D15: 3399 | E15: 53.87 | F15: 98 | G15: 677 | H15: 1439 | I15: 1050 | J15: 134 | K15: 1
A16: Humanities | B16: Total | C16: 10234 | D16: 4785 | E16: 46.76 | F16: 121 | G16: 862 | H16: 1993 | I16: 1560 | J16: 247 | K16: 2
... A22: Total | B22: Total | C22: 20763 | D22: 11856 | E22: 57.1 | F22: 866 | G22: 2213 | H22: 4518 | I22: 3753 | J22: 504 | K22: 2

Sheet BWP 2024 Regular (Affiliated)
A1: BISE Bahawalpur — General Pass Percentage — Regular (Affiliated) — Intermediate Part I & II Combined (First Annual) 2024
A2: Source: BISE Bahawalpur Result at a Glance, Intermediate Part I & II Combined (First Annual) 2024 gazette. Pass % as published.
A4: Group | B4: Gender | C4: Appeared | D4: Pass | E4: Pass % | F4: A+ | G4: A | H4: B | I4: C | J4: D | K4: E
A5: Pre Medical | B5: Male | C5: 3678 | D5: 3150 | E5: 85.64 | F5: 842 | G5: 781 | H5: 883 | I5: 593 | J5: 51 | K5: 0
A6: Pre Medical | B6: Female | C6: 7638 | D6: 6904 | E6: 90.39 | F6: 2173 | G6: 2095 | H6: 1747 | I6: 851 | J6: 38 | K6: 0
A7: Pre Medical | B7: Total | C7: 11316 | D7: 10054 | E7: 88.85 | F7: 3015 | G7: 2876 | H7: 2630 | I7: 1444 | J7: 89 | K7: 0
A8: Pre Engineering | B8: Male | C8: 1181 | D8: 947 | E8: 80.19 | F8: 162 | G8: 238 | H8: 293 | I8: 229 | J8: 25 | K8: 0
A9: Pre Engineering | B9: Female | C9: 681 | D9: 595 | E9: 87.37 | F9: 137 | G9: 192 | H9: 180 | I9: 83 | J9: 3 | K9: 0
A10: Pre Engineering | B10: Total | C10: 1862 | D10: 1542 | E10: 82.81 | F10: 299 | G10: 430 | H10: 473 | I10: 312 | J10: 28 | K10: 0
A11: General Science | B11: Male | C11: 3601 | D11: 2052 | E11: 56.98 | F11: 140 | G11: 382 | H11: 702 | I11: 710 | J11: 118 | K11: 0
A12: General Science | B12: Female | C12: 2544 | D12: 1845 | E12: 72.52 | F12: 176 | G12: 472 | H12: 672 | I12: 480 | J12: 45 | K12: 0
A13: General Science | B13: Total | C13: 6145 | D13: 3897 | E13: 63.42 | F13: 316 | G13: 854 | H13: 1374 | I13: 1190 | J13: 163 | K13: 0
A14: Humanities | B14: Male | C14: 1809 | D14: 848 | E14: 46.88 | F14: 21 | G14: 85 | H14: 317 | I14: 323 | J14: 102 | K14: 0
A15: Humanities | B15: Female | C15: 1985 | D15: 1301 | E15: 65.54 | F15: 64 | G15: 354 | H15: 545 | I15: 314 | J15: 24 | K15: 0
A16: Humanities | B16: Total | C16: 3794 | D16: 2149 | E16: 56.64 | F16: 85 | G16: 439 | H16: 862 | I16: 637 | J16: 126 | K16: 0
... A22: Total | B22: Total | C22: 23259 | D22: 17741 | E22: 76.28 | F22: 3732 | G22: 4629 | H22: 5371 | I22: 3599 | J22: 410 | K22: 0

Sheet BWP 2024 Total (Regular)
A1: BISE Bahawalpur — General Pass Percentage — Total (Regular) — Intermediate Part I & II Combined (First Annual) 2024
A2: Source: BISE Bahawalpur Result at a Glance, Intermediate Part I & II Combined (First Annual) 2024 gazette. Pass % as published.
A4: Group | B4: Gender | C4: Appeared | D4: Pass | E4: Pass % | F4: A+ | G4: A | H4: B | I4: C | J4: D | K4: E
A5: Pre Medical | B5: Male | C5: 5108 | D5: 4259 | E5: 83.38 | F5: 1051 | G5: 1021 | H5: 1226 | I5: 876 | J5: 85 | K5: 0
A6: Pre Medical | B6: Female | C6: 11091 | D6: 9725 | E6: 87.68 | F6: 2567 | G6: 2740 | H6: 2812 | I6: 1530 | J6: 76 | K6: 0
A7: Pre Medical | B7: Total | C7: 16199 | D7: 13984 | E7: 86.33 | F7: 3618 | G7: 3761 | H7: 4038 | I7: 2406 | J7: 161 | K7: 0
A8: Pre Engineering | B8: Male | C8: 1652 | D8: 1277 | E8: 77.3 | F8: 197 | G8: 300 | H8: 401 | I8: 334 | J8: 45 | K8: 0
A9: Pre Engineering | B9: Female | C9: 1037 | D9: 880 | E9: 84.86 | F9: 164 | G9: 249 | H9: 288 | I9: 167 | J9: 12 | K9: 0
A10: Pre Engineering | B10: Total | C10: 2689 | D10: 2157 | E10: 80.22 | F10: 361 | G10: 549 | H10: 689 | I10: 501 | J10: 57 | K10: 0
A11: General Science | B11: Male | C11: 5863 | D11: 3057 | E11: 52.14 | F11: 164 | G11: 516 | H11: 1021 | I11: 1143 | J11: 213 | K11: 0
A12: General Science | B12: Female | C12: 5050 | D12: 3338 | E12: 66.1 | F12: 230 | G12: 684 | H12: 1238 | I12: 1080 | J12: 106 | K12: 0
A13: General Science | B13: Total | C13: 10913 | D13: 6395 | E13: 58.6 | F13: 394 | G13: 1200 | H13: 2259 | I13: 2223 | J13: 319 | K13: 0
A14: Humanities | B14: Male | C14: 5733 | D14: 2234 | E14: 38.97 | F14: 44 | G14: 270 | H14: 871 | I14: 833 | J14: 215 | K14: 1
A15: Humanities | B15: Female | C15: 8295 | D15: 4700 | E15: 56.66 | F15: 162 | G15: 1031 | H15: 1984 | I15: 1364 | J15: 158 | K15: 1
A16: Humanities | B16: Total | C16: 14028 | D16: 6934 | E16: 49.43 | F16: 206 | G16: 1301 | H16: 2855 | I16: 2197 | J16: 373 | K16: 2
... A22: Total | B22: Total | C22: 44022 | D22: 29597 | E22: 67.23 | F22: 4598 | G22: 6842 | H22: 9889 | I22: 7352 | J22: 914 | K22: 2

Sheet BWP 2024 Private
A1: BISE Bahawalpur — General Pass Percentage — Private — Intermediate Part I & II Combined (First Annual) 2024
A2: Source: BISE Bahawalpur Result at a Glance, Intermediate Part I & II Combined (First Annual) 2024 gazette. Pass % as published.
A4: Group | B4: Gender | C4: Appeared | D4: Pass | E4: Pass % | F4: A+ | G4: A | H4: B | I4: C | J4: D | K4: E
A5: Pre Medical | B5: Male | C5: 1145 | D5: 629 | E5: 54.93 | F5: 225 | G5: 53 | H5: 52 | I5: 146 | J5: 150 | K5: 3
A6: Pre Medical | B6: Female | C6: 1688 | D6: 1136 | E6: 67.3 | F6: 540 | G6: 106 | H6: 94 | I6: 245 | J6: 149 | K6: 2
A7: Pre Medical | B7: Total | C7: 2833 | D7: 1765 | E7: 62.3 | F7: 765 | G7: 159 | H7: 146 | I7: 391 | J7: 299 | K7: 5
A8: Pre Engineering | B8: Male | C8: 444 | D8: 183 | E8: 41.22 | F8: 3 | G8: 12 | H8: 19 | I8: 55 | J8: 90 | K8: 4
A9: Pre Engineering | B9: Female | C9: 147 | D9: 65 | E9: 44.22 | F9: 2 | G9: 6 | H9: 9 | I9: 23 | J9: 23 | K9: 2
A10: Pre Engineering | B10: Total | C10: 591 | D10: 248 | E10: 41.96 | F10: 5 | G10: 18 | H10: 28 | I10: 78 | J10: 113 | K10: 6
A11: General Science | B11: Male | C11: 1066 | D11: 328 | E11: 30.77 | F11: 0 | G11: 6 | H11: 18 | I11: 96 | J11: 200 | K11: 8
A12: General Science | B12: Female | C12: 631 | D12: 236 | E12: 37.4 | F12: 1 | G12: 1 | H12: 11 | I12: 92 | J12: 129 | K12: 2
A13: General Science | B13: Total | C13: 1697 | D13: 564 | E13: 33.24 | F13: 1 | G13: 7 | H13: 29 | I13: 188 | J13: 329 | K13: 10
A14: Humanities | B14: Male | C14: 4733 | D14: 1148 | E14: 24.26 | F14: 17 | G14: 77 | H14: 236 | I14: 468 | J14: 323 | K14: 27
A15: Humanities | B15: Female | C15: 3672 | D15: 1334 | E15: 36.33 | F15: 33 | G15: 163 | H15: 430 | I15: 473 | J15: 219 | K15: 16
A16: Humanities | B16: Total | C16: 8405 | D16: 2482 | E16: 29.53 | F16: 50 | G16: 240 | H16: 666 | I16: 941 | J16: 542 | K16: 43
... A22: Total | B22: Total | C22: 13638 | D22: 5092 | E22: 37.34 | F22: 821 | G22: 425 | H22: 878 | I22: 1608 | J22: 1296 | K22: 64

Sheet BWP 2024 Grand Total
A1: BISE Bahawalpur — General Pass Percentage — Grand Total (Regular + Private) — Intermediate Part I & II Combined (First Annual) 2024
A2: Source: BISE Bahawalpur Result at a Glance, Intermediate Part I & II Combined (First Annual) 2024 gazette. Pass % as published.
A4: Group | B4: Gender | C4: Appeared | D4: Pass | E4: Pass % | F4: A+ | G4: A | H4: B | I4: C | J4: D | K4: E
A5: Pre Medical | B5: Male | C5: 6253 | D5: 4888 | E5: 78.17 | F5: 1276 | G5: 1074 | H5: 1278 | I5: 1022 | J5: 235 | K5: 3
A6: Pre Medical | B6: Female | C6: 12779 | D6: 10861 | E6: 84.99 | F6: 3107 | G6: 2846 | H6: 2906 | I6: 1775 | J6: 225 | K6: 2
A7: Pre Medical | B7: Total | C7: 19032 | D7: 15749 | E7: 82.75 | F7: 4383 | G7: 3920 | H7: 4184 | I7: 2797 | J7: 460 | K7: 5
A8: Pre Engineering | B8: Male | C8: 2096 | D8: 1460 | E8: 69.66 | F8: 200 | G8: 312 | H8: 420 | I8: 389 | J8: 135 | K8: 4
A9: Pre Engineering | B9: Female | C9: 1184 | D9: 945 | E9: 79.81 | F9: 166 | G9: 255 | H9: 297 | I9: 190 | J9: 35 | K9: 2
A10: Pre Engineering | B10: Total | C10: 3280 | D10: 2405 | E10: 73.32 | F10: 366 | G10: 567 | H10: 717 | I10: 579 | J10: 170 | K10: 6
A11: General Science | B11: Male | C11: 6929 | D11: 3385 | E11: 48.85 | F11: 164 | G11: 522 | H11: 1039 | I11: 1239 | J11: 413 | K11: 8
A12: General Science | B12: Female | C12: 5681 | D12: 3574 | E12: 62.91 | F12: 231 | G12: 685 | H12: 1249 | I12: 1172 | J12: 235 | K12: 2
A13: General Science | B13: Total | C13: 12610 | D13: 6959 | E13: 55.19 | F13: 395 | G13: 1207 | H13: 2288 | I13: 2411 | J13: 648 | K13: 10
A14: Humanities | B14: Male | C14: 10466 | D14: 3382 | E14: 32.31 | F14: 61 | G14: 347 | H14: 1107 | I14: 1301 | J14: 538 | K14: 28
A15: Humanities | B15: Female | C15: 11967 | D15: 6034 | E15: 50.42 | F15: 195 | G15: 1194 | H15: 2414 | I15: 1837 | J15: 377 | K15: 17
A16: Humanities | B16: Total | C16: 22433 | D16: 9416 | E16: 41.97 | F16: 256 | G16: 1541 | H16: 3521 | I16: 3138 | J16: 915 | K16: 45
... A22: Total | B22: Total | C22: 57660 | D22: 34689 | E22: 60.16 | F22: 5419 | G22: 7267 | H22: 10767 | I22: 8960 | J22: 2210 | K22: 66

Sheet BWP 2024 District Wise Pass %
A1: BISE Bahawalpur — District Wise Pass Percentage (2022 - 2024) — Intermediate First Annual
A2: Source: 2024 gazette (district table also lists 2022 and 2023 for comparison). Pass % as published.
A4: Year | B4: District | C4: Male Appeared | D4: Male Passed | E4: Male % | F4: Female Appeared | G4: Female Passed | H4: Female % | I4: Total Appeared | J4: Total Passed | K4: Total %
A5: 2024 | B5: Bahawalpur | C5: 9069 | D5: 4768 | E5: 52.57 | F5: 11017 | G5: 7742 | H5: 70.27 | I5: 20086 | J5: 12510 | K5: 62.28
A6: 2024 | B6: Bahawalnagar | C6: 7220 | D6: 3401 | E6: 47.11 | F6: 9304 | G6: 6071 | H6: 65.25 | I6: 16524 | J6: 9472 | K6: 57.32
A7: 2024 | B7: Rahimyar Khan | C7: 9687 | D7: 5049 | E7: 52.12 | F7: 11363 | G7: 7658 | H7: 67.39 | I7: 21050 | J7: 12707 | K7: 60.37
A8: 2024 | B8: Total | C8: 25976 | D8: 13218 | E8: 50.89 | F8: 31684 | G8: 21471 | H8: 67.77 | I8: 57660 | J8: 34689 | K8: 60.16
A9: 2023 | B9: Bahawalpur | C9: 9206 | D9: 4645 | E9: 50.46 | F9: 10417 | G9: 6977 | H9: 66.98 | I9: 19623 | J9: 11622 | K9: 59.23
A10: 2023 | B10: Bahawalnagar | C10: 7190 | D10: 3248 | E10: 45.17 | F10: 9132 | G10: 5693 | H10: 62.34 | I10: 16322 | J10: 8941 | K10: 54.78
A11: 2023 | B11: Rahimyar Khan | C11: 9943 | D11: 4907 | E11: 49.35 | F11: 11555 | G11: 7541 | H11: 65.26 | I11: 21498 | J11: 12448 | K11: 57.9
A12: 2023 | B12: Total | C12: 26339 | D12: 12800 | E12: 48.6 | F12: 31104 | G12: 20211 | H12: 64.98 | I12: 57443 | J12: 33011 | K12: 57.47
A13: 2022 | B13: Bahawalpur | C13: 7925 | D13: 5514 | E13: 69.58 | F13: 9267 | G13: 7864 | H13: 84.86 | I13: 17192 | J13: 13378 | K13: 77.82
A14: 2022 | B14: Bahawalnagar | C14: 5976 | D14: 4101 | E14: 68.62 | F14: 7856 | G14: 6688 | H14: 85.13 | I14: 13832 | J14: 10789 | K14: 78
A15: 2022 | B15: Rahimyar Khan | C15: 8110 | D15: 5433 | E15: 66.99 | F15: 9315 | G15: 7558 | H15: 81.14 | I15: 17425 | J15: 12991 | K15: 74.55
A16: 2022 | B16: Total | C16: 22011 | D16: 15048 | E16: 68.37 | F16: 26438 | G16: 22110 | H16: 83.63 | I16: 48449 | J16: 37158 | K16: 76.7

Sheet BWP 2024 Subject Wise Pass %
A1: BISE Bahawalpur — Subject Wise Pass Percentage — Intermediate Part I & II Combined (First Annual) 2024
A2: Source: BISE Bahawalpur Result at a Glance, Intermediate Part I & II Combined (First Annual) 2024 gazette. Pass % as published. Entries kept exactly as published: "Ethics-I (For Non Muslims)" appears twice (Sr. 26 & 27); two History of Islam-II names are truncated in the gazette.
A4: Year | B4: Subject Name | C4: Appeared | D4: Passed | E4: Pass %
A5: 2024 | B5: Arabic-I | C5: 136 | D5: 122 | E5: 89.71
A6: 2024 | B6: Arabic-II | C6: 1467 | D6: 1402 | E6: 95.57
A7: 2024 | B7: Banking | C7: 239 | D7: 239 | E7: 100
A8: 2024 | B8: Biology-I | C8: 3504 | D8: 2376 | E8: 67.81
A9: 2024 | B9: Biology-II | C9: 17493 | D9: 15940 | E9: 91.12
A10: 2024 | B10: Business Mathematics | C10: 14 | D10: 12 | E10: 85.71
A11: 2024 | B11: Business Statistics | C11: 244 | D11: 218 | E11: 89.34
A12: 2024 | B12: Chemistry-I | C12: 3953 | D12: 1836 | E12: 46.45
A13: 2024 | B13: Chemistry-II | C13: 20881 | D13: 17787 | E13: 85.18
A14: 2024 | B14: Civics-I | C14: 1151 | D14: 1047 | E14: 90.96
A15: 2024 | B15: Civics-I (For Non Muslims) | C15: 0 | D15: 0 | E15: 0
A16: 2024 | B16: Civics-II | C16: 3952 | D16: 3477 | E16: 87.98
... A86: 2024 | B86: Urdu-II | C86: 48832 | D86: 47485 | E86: 97.24

Sheet BWP 2025 Regular (Govt.)
A1: BISE Bahawalpur — General Pass Percentage — Regular (Govt.) — Intermediate Part I & II Combined (First Annual) 2025
A2: Source: BISE Bahawalpur Result Gazette, Intermediate Part I & II Combined (First Annual) 2025 (supplied PDF). Pass % as published.
A4: Group | B4: Gender | C4: Appeared | D4: Pass | E4: Pass % | F4: A+ | G4: A | H4: B | I4: C | J4: D | K4: E
A5: Pre Medical | B5: Male | C5: 977 | D5: 667 | E5: 68.27 | F5: 106 | G5: 148 | H5: 198 | I5: 193 | J5: 22 | K5: 0
A6: Pre Medical | B6: Female | C6: 2734 | D6: 2281 | E6: 83.43 | F6: 394 | G6: 577 | H6: 814 | I6: 473 | J6: 23 | K6: 0
A7: Pre Medical | B7: Total | C7: 3711 | D7: 2948 | E7: 79.44 | F7: 500 | G7: 725 | H7: 1012 | I7: 666 | J7: 45 | K7: 0
A8: Pre Engineering | B8: Male | C8: 307 | D8: 211 | E8: 68.73 | F8: 38 | G8: 44 | H8: 58 | I8: 55 | J8: 16 | K8: 0
A9: Pre Engineering | B9: Female | C9: 232 | D9: 194 | E9: 83.62 | F9: 28 | G9: 48 | H9: 69 | I9: 44 | J9: 5 | K9: 0
A10: Pre Engineering | B10: Total | C10: 539 | D10: 405 | E10: 75.14 | F10: 66 | G10: 92 | H10: 127 | I10: 99 | J10: 21 | K10: 0
A11: General Science | B11: Male | C11: 2583 | D11: 1300 | E11: 50.33 | F11: 73 | G11: 150 | H11: 465 | I11: 501 | J11: 111 | K11: 0
A12: General Science | B12: Female | C12: 2670 | D12: 1800 | E12: 67.42 | F12: 92 | G12: 326 | H12: 740 | I12: 573 | J12: 69 | K12: 0
A13: General Science | B13: Total | C13: 5253 | D13: 3100 | E13: 59.01 | F13: 165 | G13: 476 | H13: 1205 | I13: 1074 | J13: 180 | K13: 0
A14: Humanities | B14: Male | C14: 3745 | D14: 1420 | E14: 37.92 | F14: 30 | G14: 148 | H14: 507 | I14: 566 | J14: 167 | K14: 2
A15: Humanities | B15: Female | C15: 6756 | D15: 4164 | E15: 61.63 | F15: 155 | G15: 896 | H15: 1779 | I15: 1143 | J15: 186 | K15: 5
A16: Humanities | B16: Total | C16: 10501 | D16: 5584 | E16: 53.18 | F16: 185 | G16: 1044 | H16: 2286 | I16: 1709 | J16: 353 | K16: 7
... A22: Total | B22: Total | C22: 20073 | D22: 12087 | E22: 60.22 | F22: 918 | G22: 2348 | H22: 4644 | I22: 3564 | J22: 606 | K22: 7

Sheet BWP 2025 Regular (Affiliated)
A1: BISE Bahawalpur — General Pass Percentage — Regular (Affiliated) — Intermediate Part I & II Combined (First Annual) 2025
A2: Source: BISE Bahawalpur Result Gazette, Intermediate Part I & II Combined (First Annual) 2025 (supplied PDF). Pass % as published.
A4: Group | B4: Gender | C4: Appeared | D4: Pass | E4: Pass % | F4: A+ | G4: A | H4: B | I4: C | J4: D | K4: E
A5: Pre Medical | B5: Male | C5: 2488 | D5: 2059 | E5: 82.76 | F5: 555 | G5: 520 | H5: 567 | I5: 378 | J5: 39 | K5: 0
A6: Pre Medical | B6: Female | C6: 6409 | D6: 5757 | E6: 89.83 | F6: 1972 | G6: 1685 | H6: 1463 | I6: 604 | J6: 32 | K6: 1
A7: Pre Medical | B7: Total | C7: 8897 | D7: 7816 | E7: 87.85 | F7: 2527 | G7: 2205 | H7: 2030 | I7: 982 | J7: 71 | K7: 1
A8: Pre Engineering | B8: Male | C8: 888 | D8: 758 | E8: 85.36 | F8: 175 | G8: 207 | H8: 230 | I8: 125 | J8: 21 | K8: 0
A9: Pre Engineering | B9: Female | C9: 528 | D9: 485 | E9: 91.86 | F9: 130 | G9: 163 | H9: 126 | I9: 62 | J9: 4 | K9: 0
A10: Pre Engineering | B10: Total | C10: 1416 | D10: 1243 | E10: 87.78 | F10: 305 | G10: 370 | H10: 356 | I10: 187 | J10: 25 | K10: 0
A11: General Science | B11: Male | C11: 4255 | D11: 2799 | E11: 65.78 | F11: 270 | G11: 582 | H11: 933 | I11: 838 | J11: 176 | K11: 0
A12: General Science | B12: Female | C12: 3847 | D12: 3039 | E12: 79 | F12: 483 | G12: 894 | H12: 1098 | I12: 522 | J12: 42 | K12: 0
A13: General Science | B13: Total | C13: 8102 | D13: 5838 | E13: 72.06 | F13: 753 | G13: 1476 | H13: 2031 | I13: 1360 | J13: 218 | K13: 0
A14: Humanities | B14: Male | C14: 2121 | D14: 1047 | E14: 49.36 | F14: 15 | G14: 113 | H14: 319 | I14: 415 | J14: 181 | K14: 4
A15: Humanities | B15: Female | C15: 2859 | D15: 2114 | E15: 73.94 | F15: 108 | G15: 534 | H15: 894 | I15: 504 | J15: 74 | K15: 0
A16: Humanities | B16: Total | C16: 4980 | D16: 3161 | E16: 63.47 | F16: 123 | G16: 647 | H16: 1213 | I16: 919 | J16: 255 | K16: 4
... A22: Total | B22: Total | C22: 23518 | D22: 18143 | E22: 77.15 | F22: 3715 | G22: 4718 | H22: 5653 | I22: 3473 | J22: 579 | K22: 5

Sheet BWP 2025 Total (Regular)
A1: BISE Bahawalpur — General Pass Percentage — Total (Regular) — Intermediate Part I & II Combined (First Annual) 2025
A2: Source: BISE Bahawalpur Result Gazette, Intermediate Part I & II Combined (First Annual) 2025 (supplied PDF). Pass % as published.
A4: Group | B4: Gender | C4: Appeared | D4: Pass | E4: Pass % | F4: A+ | G4: A | H4: B | I4: C | J4: D | K4: E
A5: Pre Medical | B5: Male | C5: 3465 | D5: 2726 | E5: 78.67 | F5: 661 | G5: 668 | H5: 765 | I5: 571 | J5: 61 | K5: 0
A6: Pre Medical | B6: Female | C6: 9143 | D6: 8038 | E6: 87.91 | F6: 2366 | G6: 2262 | H6: 2277 | I6: 1077 | J6: 55 | K6: 1
A7: Pre Medical | B7: Total | C7: 12608 | D7: 10764 | E7: 85.37 | F7: 3027 | G7: 2930 | H7: 3042 | I7: 1648 | J7: 116 | K7: 1
A8: Pre Engineering | B8: Male | C8: 1195 | D8: 969 | E8: 81.09 | F8: 213 | G8: 251 | H8: 288 | I8: 180 | J8: 37 | K8: 0
A9: Pre Engineering | B9: Female | C9: 760 | D9: 679 | E9: 89.34 | F9: 158 | G9: 211 | H9: 195 | I9: 106 | J9: 9 | K9: 0
A10: Pre Engineering | B10: Total | C10: 1955 | D10: 1648 | E10: 84.3 | F10: 371 | G10: 462 | H10: 483 | I10: 286 | J10: 46 | K10: 0
A11: General Science | B11: Male | C11: 6838 | D11: 4099 | E11: 59.94 | F11: 343 | G11: 732 | H11: 1398 | I11: 1339 | J11: 287 | K11: 0
A12: General Science | B12: Female | C12: 6517 | D12: 4839 | E12: 74.25 | F12: 575 | G12: 1220 | H12: 1838 | I12: 1095 | J12: 111 | K12: 0
A13: General Science | B13: Total | C13: 13355 | D13: 8938 | E13: 66.93 | F13: 918 | G13: 1952 | H13: 3236 | I13: 2434 | J13: 398 | K13: 0
A14: Humanities | B14: Male | C14: 5866 | D14: 2467 | E14: 42.06 | F14: 45 | G14: 261 | H14: 826 | I14: 981 | J14: 348 | K14: 6
A15: Humanities | B15: Female | C15: 9615 | D15: 6278 | E15: 65.29 | F15: 263 | G15: 1430 | H15: 2673 | I15: 1647 | J15: 260 | K15: 5
A16: Humanities | B16: Total | C16: 15481 | D16: 8745 | E16: 56.49 | F16: 308 | G16: 1691 | H16: 3499 | I16: 2628 | J16: 608 | K16: 11
... A22: Total | B22: Total | C22: 43591 | D22: 30230 | E22: 69.35 | F22: 4633 | G22: 7066 | H22: 10297 | I22: 7037 | J22: 1185 | K22: 12

Sheet BWP 2025 Private
A1: BISE Bahawalpur — General Pass Percentage — Private — Intermediate Part I & II Combined (First Annual) 2025
A2: Source: BISE Bahawalpur Result Gazette, Intermediate Part I & II Combined (First Annual) 2025 (supplied PDF). Pass % as published.
A4: Group | B4: Gender | C4: Appeared | D4: Pass | E4: Pass % | F4: A+ | G4: A | H4: B | I4: C | J4: D | K4: E
A5: Pre Medical | B5: Male | C5: 798 | D5: 500 | E5: 62.66 | F5: 284 | G5: 27 | H5: 53 | I5: 91 | J5: 45 | K5: 0
A6: Pre Medical | B6: Female | C6: 1594 | D6: 1177 | E6: 73.84 | F6: 687 | G6: 137 | H6: 92 | I6: 197 | J6: 64 | K6: 0
A7: Pre Medical | B7: Total | C7: 2392 | D7: 1677 | E7: 70.11 | F7: 971 | G7: 164 | H7: 145 | I7: 288 | J7: 109 | K7: 0
A8: Pre Engineering | B8: Male | C8: 249 | D8: 122 | E8: 49 | F8: 11 | G8: 5 | H8: 24 | I8: 39 | J8: 40 | K8: 3
A9: Pre Engineering | B9: Female | C9: 94 | D9: 48 | E9: 51.06 | F9: 8 | G9: 2 | H9: 3 | I9: 19 | J9: 13 | K9: 3
A10: Pre Engineering | B10: Total | C10: 343 | D10: 170 | E10: 49.56 | F10: 19 | G10: 7 | H10: 27 | I10: 58 | J10: 53 | K10: 6
A11: General Science | B11: Male | C11: 1128 | D11: 412 | E11: 36.52 | F11: 0 | G11: 1 | H11: 26 | I11: 217 | J11: 164 | K11: 4
A12: General Science | B12: Female | C12: 685 | D12: 265 | E12: 38.69 | F12: 0 | G12: 6 | H12: 28 | I12: 165 | J12: 65 | K12: 1
A13: General Science | B13: Total | C13: 1813 | D13: 677 | E13: 37.34 | F13: 0 | G13: 7 | H13: 54 | I13: 382 | J13: 229 | K13: 5
A14: Humanities | B14: Male | C14: 3893 | D14: 1006 | E14: 25.84 | F14: 4 | G14: 63 | H14: 259 | I14: 437 | J14: 234 | K14: 9
A15: Humanities | B15: Female | C15: 3609 | D15: 1624 | E15: 45 | F15: 23 | G15: 215 | H15: 588 | I15: 630 | J15: 167 | K15: 1
A16: Humanities | B16: Total | C16: 7502 | D16: 2630 | E16: 35.06 | F16: 27 | G16: 278 | H16: 847 | I16: 1067 | J16: 401 | K16: 10
... A22: Total | B22: Total | C22: 12136 | D22: 5174 | E22: 42.63 | F22: 1018 | G22: 456 | H22: 1079 | I22: 1800 | J22: 799 | K22: 22

Sheet BWP 2025 Grand Total
A1: BISE Bahawalpur — General Pass Percentage — Grand Total (Regular + Private) — Intermediate Part I & II Combined (First Annual) 2025
A2: Source: BISE Bahawalpur Result Gazette, Intermediate Part I & II Combined (First Annual) 2025 (supplied PDF). Pass % as published.
A4: Group | B4: Gender | C4: Appeared | D4: Pass | E4: Pass % | F4: A+ | G4: A | H4: B | I4: C | J4: D | K4: E
A5: Pre Medical | B5: Male | C5: 4263 | D5: 3226 | E5: 75.67 | F5: 945 | G5: 695 | H5: 818 | I5: 662 | J5: 106 | K5: 0
A6: Pre Medical | B6: Female | C6: 10737 | D6: 9215 | E6: 85.82 | F6: 3053 | G6: 2399 | H6: 2369 | I6: 1274 | J6: 119 | K6: 1
A7: Pre Medical | B7: Total | C7: 15000 | D7: 12441 | E7: 82.94 | F7: 3998 | G7: 3094 | H7: 3187 | I7: 1936 | J7: 225 | K7: 1
A8: Pre Engineering | B8: Male | C8: 1444 | D8: 1091 | E8: 75.55 | F8: 224 | G8: 256 | H8: 312 | I8: 219 | J8: 77 | K8: 3
A9: Pre Engineering | B9: Female | C9: 854 | D9: 727 | E9: 85.13 | F9: 166 | G9: 213 | H9: 198 | I9: 125 | J9: 22 | K9: 3
A10: Pre Engineering | B10: Total | C10: 2298 | D10: 1818 | E10: 79.11 | F10: 390 | G10: 469 | H10: 510 | I10: 344 | J10: 99 | K10: 6
A11: General Science | B11: Male | C11: 7966 | D11: 4511 | E11: 56.63 | F11: 343 | G11: 733 | H11: 1424 | I11: 1556 | J11: 451 | K11: 4
A12: General Science | B12: Female | C12: 7202 | D12: 5104 | E12: 70.87 | F12: 575 | G12: 1226 | H12: 1866 | I12: 1260 | J12: 176 | K12: 1
A13: General Science | B13: Total | C13: 15168 | D13: 9615 | E13: 63.39 | F13: 918 | G13: 1959 | H13: 3290 | I13: 2816 | J13: 627 | K13: 5
A14: Humanities | B14: Male | C14: 9759 | D14: 3473 | E14: 35.59 | F14: 49 | G14: 324 | H14: 1085 | I14: 1418 | J14: 582 | K14: 15
A15: Humanities | B15: Female | C15: 13224 | D15: 7902 | E15: 59.75 | F15: 286 | G15: 1645 | H15: 3261 | I15: 2277 | J15: 427 | K15: 6
A16: Humanities | B16: Total | C16: 22983 | D16: 11375 | E16: 49.49 | F16: 335 | G16: 1969 | H16: 4346 | I16: 3695 | J16: 1009 | K16: 21
... A22: Total | B22: Total | C22: 55727 | D22: 35404 | E22: 63.53 | F22: 5651 | G22: 7522 | H22: 11376 | I22: 8837 | J22: 1984 | K22: 34

Sheet BWP 2025 Subject Wise Pass %
A1: BISE Bahawalpur — Subject Wise Pass Percentage — Intermediate Part I & II Combined (First Annual) 2025
A2: Source: BISE Bahawalpur Result Gazette, Intermediate Part I & II Combined (First Annual) 2025 (supplied PDF). Pass % as published. Only the first 45 subject entries (Arabic-I to Library Science-II) were on the supplied page; remaining subjects are not included yet.
A4: Year | B4: Subject Name | C4: Appeared | D4: Passed | E4: Pass %
A5: 2025 | B5: Arabic-I | C5: 194 | D5: 155 | E5: 79.9
A6: 2025 | B6: Arabic-II | C6: 1345 | D6: 1244 | E6: 92.49
A7: 2025 | B7: Banking | C7: 223 | D7: 214 | E7: 95.96
A8: 2025 | B8: Biology-I | C8: 2419 | D8: 1284 | E8: 53.08
A9: 2025 | B9: Biology-II | C9: 13558 | D9: 11501 | E9: 84.83
A10: 2025 | B10: Business Mathematics | C10: 21 | D10: 14 | E10: 66.67
A11: 2025 | B11: Business Statistics | C11: 238 | D11: 224 | E11: 94.12
A12: 2025 | B12: Chemistry-I | C12: 3296 | D12: 1781 | E12: 54.04
A13: 2025 | B13: Chemistry-II | C13: 15842 | D13: 13922 | E13: 87.88
A14: 2025 | B14: Civics-I | C14: 1138 | D14: 1013 | E14: 89.02
A15: 2025 | B15: Civics-II | C15: 4038 | D15: 3707 | E15: 91.8
A16: 2025 | B16: Commercial Geography | C16: 235 | D16: 222 | E16: 94.47
... A49: 2025 | B49: Library Science-II | C49: 2786 | D49: 2760 | E49: 99.07

Sheet BWP 2026 Result at a Glance
A1: BOARD OF INTERMEDIATE AND SECONDARY EDUCATION BAHAWALPUR — Result at a Glance, Intermediate Part I & II Combined (First Annual) 2026
A2: Item E in the gazette is labelled "Pass Percentage of candidates who appeared" (Regular 66.01 / Private 36.09 / Overall 59.92). Applied 61,668 − absent & cancelled 1,076 = appeared 60,592.
A4: Item | B4: Category | C4: Value
A5: Total number of candidates who applied for admission | C5: 61668
A6: Total number of absent candidates & Cancelled Roll No | C6: 1076
A7: Total number of candidates who appeared | B7: Regular | C7: 48249
A8: Total number of candidates who appeared | B8: Private | C8: 12343
A9: Total number of candidates who appeared | B9: Total | C9: 60592
A10: Number of successful candidates | B10: Regular | C10: 31850
A11: Number of successful candidates | B11: Private | C11: 4454
A12: Number of successful candidates | B12: Total | C12: 36304
A13: Pass percentage | B13: Regular | C13: 66.01
A14: Pass percentage | B14: Private | C14: 36.09
A15: Pass percentage | B15: Overall | C15: 59.92

Sheet BWP 2026 Regular (Govt.)
A1: BISE Bahawalpur — General Pass Percentage — Regular (Govt.) — Intermediate Part I & II Combined (First Annual) 2026
A2: Source: BISE Bahawalpur Result Gazette, Intermediate Part I & II Combined (First Annual) 2026 (supplied PDF). Pass % as published.
A4: Pre Medical | B4: Male | C4: 1059 | D4: 657 | E4: 62.04 | F4: 117 | G4: 122 | H4: 206 | I4: 195 | J4: 17 | K4: 0
A5: Pre Medical | B5: Female | C5: 3081 | D5: 2329 | E5: 75.59 | F5: 399 | G5: 561 | H5: 809 | I5: 533 | J5: 27 | K5: 0
A6: Pre Medical | B6: Total | C6: 4140 | D6: 2986 | E6: 72.13 | F6: 516 | G6: 683 | H6: 1015 | I6: 728 | J6: 44 | K6: 0
A7: Pre Engineering | B7: Male | C7: 285 | D7: 190 | E7: 66.67 | F7: 34 | G7: 42 | H7: 57 | I7: 51 | J7: 6 | K7: 0
A8: Pre Engineering | B8: Female | C8: 165 | D8: 126 | E8: 76.36 | F8: 13 | G8: 26 | H8: 48 | I8: 35 | J8: 4 | K8: 0
A9: Pre Engineering | B9: Total | C9: 450 | D9: 316 | E9: 70.22 | F9: 47 | G9: 68 | H9: 105 | I9: 86 | J9: 10 | K9: 0
A10: General Science | B10: Male | C10: 3120 | D10: 1422 | E10: 45.58 | F10: 96 | G10: 214 | H10: 421 | I10: 575 | J10: 116 | K10: 0
A11: General Science | B11: Female | C11: 3298 | D11: 2163 | E11: 65.59 | F11: 163 | G11: 414 | H11: 806 | I11: 690 | J11: 90 | K11: 0
A12: General Science | B12: Total | C12: 6418 | D12: 3585 | E12: 55.86 | F12: 259 | G12: 628 | H12: 1227 | I12: 1265 | J12: 206 | K12: 0
A13: Humanities | B13: Male | C13: 4094 | D13: 1431 | E13: 34.95 | F13: 18 | G13: 164 | H13: 482 | I13: 569 | J13: 192 | K13: 6
A14: Humanities | B14: Female | C14: 6974 | D14: 4193 | E14: 60.12 | F14: 154 | G14: 862 | H14: 1732 | I14: 1234 | J14: 210 | K14: 1
A15: Humanities | B15: Total | C15: 11068 | D15: 5624 | E15: 50.81 | F15: 172 | G15: 1026 | H15: 2214 | I15: 1803 | J15: 402 | K15: 7
... A22: Total | B22: Total | C22: 20073 | D22: 12087 | E22: 60.22 | F22: 918 | G22: 2348 | H22: 4644 | I22: 3564 | J22: 606 | K22: 7

Sheet BWP 2026 Regular (Affiliated)
A1: BISE Bahawalpur — General Pass Percentage — Regular (Affiliated) — Intermediate Part I & II Combined (First Annual) 2026
A2: Source: BISE Bahawalpur Result Gazette, Intermediate Part I & II Combined (First Annual) 2026 (supplied PDF). Pass % as published.
A4: Pre Medical | B4: Male | C4: 2218 | D4: 1660 | E4: 74.84 | F4: 412 | G4: 406 | H4: 471 | I4: 344 | J4: 26 | K4: 1
A5: Pre Medical | B5: Female | C5: 6855 | D5: 5871 | E5: 85.65 | F5: 1721 | G5: 1629 | H5: 1684 | I5: 796 | J5: 41 | K5: 0
A6: Pre Medical | B6: Total | C6: 9073 | D6: 7531 | E6: 83 | F6: 2133 | G6: 2035 | H6: 2155 | I6: 1140 | J6: 67 | K6: 1
A7: Pre Engineering | B7: Male | C7: 820 | D7: 623 | E7: 75.98 | F7: 125 | G7: 142 | H7: 198 | I7: 136 | J7: 22 | K7: 0
A8: Pre Engineering | B8: Female | C8: 429 | D8: 389 | E8: 90.68 | F8: 131 | G8: 97 | H8: 102 | I8: 54 | J8: 5 | K8: 0
A9: Pre Engineering | B9: Total | C9: 1249 | D9: 1012 | E9: 81.02 | F9: 256 | G9: 239 | H9: 300 | I9: 190 | J9: 27 | K9: 0
A10: General Science | B10: Male | C10: 5064 | D10: 3171 | E10: 62.62 | F10: 278 | G10: 646 | H10: 1023 | I10: 1025 | J10: 199 | K10: 0
A11: General Science | B11: Female | C11: 4913 | D11: 3927 | E11: 79.93 | F11: 678 | G11: 1052 | H11: 1394 | I11: 750 | J11: 53 | K11: 0
A12: General Science | B12: Total | C12: 9977 | D12: 7098 | E12: 71.14 | F12: 956 | G12: 1698 | H12: 2417 | I12: 1775 | J12: 252 | K12: 0
A13: Humanities | B13: Male | C13: 2297 | D13: 1092 | E13: 47.54 | F13: 15 | G13: 118 | H13: 340 | I13: 451 | J13: 165 | K13: 3
A14: Humanities | B14: Female | C14: 3449 | D14: 2512 | E14: 72.83 | F14: 154 | G14: 633 | H14: 973 | I14: 646 | J14: 105 | K14: 1
A15: Humanities | B15: Total | C15: 5746 | D15: 3604 | E15: 62.72 | F15: 169 | G15: 751 | H15: 1313 | I15: 1097 | J15: 270 | K15: 4
... A22: Total | B22: Total | C22: 23518 | D22: 18143 | E22: 77.15 | F22: 3715 | G22: 4718 | H22: 5653 | I22: 3473 | J22: 579 | K22: 5

Sheet BWP 2026 Total (Regular)
A1: BISE Bahawalpur — General Pass Percentage — Total (Regular) — Intermediate Part I & II Combined (First Annual) 2026
A2: Source: BISE Bahawalpur Result Gazette, Intermediate Part I & II Combined (First Annual) 2026 (supplied PDF). Pass % as published.
A4: Pre Medical | B4: Male | C4: 3277 | D4: 2317 | E4: 70.7 | F4: 529 | G4: 528 | H4: 677 | I4: 539 | J4: 43 | K4: 1
A5: Pre Medical | B5: Female | C5: 9936 | D5: 8200 | E5: 82.53 | F5: 2120 | G5: 2190 | H5: 2493 | I5: 1329 | J5: 68 | K5: 0
A6: Pre Medical | B6: Total | C6: 13213 | D6: 10517 | E6: 79.6 | F6: 2649 | G6: 2718 | H6: 3170 | I6: 1868 | J6: 111 | K6: 1
A7: Pre Engineering | B7: Male | C7: 1105 | D7: 813 | E7: 73.57 | F7: 159 | G7: 184 | H7: 255 | I7: 187 | J7: 28 | K7: 0
A8: Pre Engineering | B8: Female | C8: 594 | D8: 515 | E8: 86.7 | F8: 144 | G8: 123 | H8: 150 | I8: 89 | J8: 9 | K8: 0
A9: Pre Engineering | B9: Total | C9: 1699 | D9: 1328 | E9: 78.16 | F9: 303 | G9: 307 | H9: 405 | I9: 276 | J9: 37 | K9: 0
A10: General Science | B10: Male | C10: 8184 | D10: 4593 | E10: 56.12 | F10: 374 | G10: 860 | H10: 1444 | I10: 1600 | J10: 315 | K10: 0
A11: General Science | B11: Female | C11: 8211 | D11: 6090 | E11: 74.17 | F11: 841 | G11: 1466 | H11: 2200 | I11: 1440 | J11: 143 | K11: 0
A12: General Science | B12: Total | C12: 16395 | D12: 10683 | E12: 65.16 | F12: 1215 | G12: 2326 | H12: 3644 | I12: 3040 | J12: 458 | K12: 0
A13: Humanities | B13: Male | C13: 6391 | D13: 2523 | E13: 39.48 | F13: 33 | G13: 282 | H13: 822 | I13: 1020 | J13: 357 | K13: 9
A14: Humanities | B14: Female | C14: 10423 | D14: 6705 | E14: 64.33 | F14: 308 | G14: 1495 | H14: 2705 | I14: 1880 | J14: 315 | K14: 2
A15: Humanities | B15: Total | C15: 16814 | D15: 9228 | E15: 54.88 | F15: 341 | G15: 1777 | H15: 3527 | I15: 2900 | J15: 672 | K15: 11
... A22: Total | B22: Total | C22: 43591 | D22: 30230 | E22: 69.35 | F22: 4633 | G22: 7066 | H22: 10297 | I22: 7037 | J22: 1185 | K22: 12

Sheet BWP 2026 Private
A1: BISE Bahawalpur — General Pass Percentage — Private — Intermediate Part I & II Combined (First Annual) 2026
A2: Source: BISE Bahawalpur Result Gazette, Intermediate Part I & II Combined (First Annual) 2026 (supplied PDF). Pass % as published.
A4: Pre Medical | B4: Male | C4: 622 | D4: 298 | E4: 47.91 | F4: 152 | G4: 13 | H4: 39 | I4: 71 | J4: 23 | K4: 0
A5: Pre Medical | B5: Female | C5: 1208 | D5: 871 | E5: 72.1 | F5: 485 | G5: 97 | H5: 67 | I5: 180 | J5: 41 | K5: 1
A6: Pre Medical | B6: Total | C6: 1830 | D6: 1169 | E6: 63.88 | F6: 637 | G6: 110 | H6: 106 | I6: 251 | J6: 64 | K6: 1
A7: Pre Engineering | B7: Male | C7: 207 | D7: 76 | E7: 36.71 | F7: 5 | G7: 6 | H7: 12 | I7: 35 | J7: 12 | K7: 6
A8: Pre Engineering | B8: Female | C8: 79 | D8: 52 | E8: 65.82 | F8: 9 | G8: 2 | H8: 11 | I8: 17 | J8: 10 | K8: 3
A9: Pre Engineering | B9: Total | C9: 286 | D9: 128 | E9: 44.76 | F9: 14 | G9: 8 | H9: 23 | I9: 52 | J9: 22 | K9: 9
A10: General Science | B10: Male | C10: 1380 | D10: 396 | E10: 28.7 | F10: 3 | G10: 6 | H10: 44 | I10: 204 | J10: 139 | K10: 0
A11: General Science | B11: Female | C11: 752 | D11: 308 | E11: 40.96 | F11: 1 | G11: 0 | H11: 38 | I11: 207 | J11: 62 | K11: 0
A12: General Science | B12: Total | C12: 2132 | D12: 704 | E12: 33.02 | F12: 4 | G12: 6 | H12: 82 | I12: 411 | J12: 201 | K12: 0
A13: Humanities | B13: Male | C13: 4306 | D13: 838 | E13: 19.46 | F13: 4 | G13: 43 | H13: 147 | I13: 370 | J13: 260 | K13: 14
A14: Humanities | B14: Female | C14: 3704 | D14: 1576 | E14: 42.55 | F14: 38 | G14: 218 | H14: 518 | I14: 595 | J14: 202 | K14: 5
A15: Humanities | B15: Total | C15: 8010 | D15: 2414 | E15: 30.14 | F15: 42 | G15: 261 | H15: 665 | I15: 965 | J15: 462 | K15: 19
... A22: Total | B22: Total | C22: 12136 | D22: 5174 | E22: 42.63 | F22: 1018 | G22: 456 | H22: 1079 | I22: 1800 | J22: 799 | K22: 22

Sheet BWP 2026 Grand Total
A1: BISE Bahawalpur — General Pass Percentage — Grand Total (Regular + Private) — Intermediate Part I & II Combined (First Annual) 2026
A2: Source: BISE Bahawalpur Result Gazette, Intermediate Part I & II Combined (First Annual) 2026 (supplied PDF). Pass % as published.
A4: Pre Medical | B4: Male | C4: 3899 | D4: 2615 | E4: 67.07 | F4: 681 | G4: 541 | H4: 716 | I4: 610 | J4: 66 | K4: 1
A5: Pre Medical | B5: Female | C5: 11144 | D5: 9071 | E5: 81.4 | F5: 2605 | G5: 2287 | H5: 2560 | I5: 1509 | J5: 109 | K5: 1
A6: Pre Medical | B6: Total | C6: 15043 | D6: 11686 | E6: 77.68 | F6: 3286 | G6: 2828 | H6: 3276 | I6: 2119 | J6: 175 | K6: 2
A7: Pre Engineering | B7: Male | C7: 1312 | D7: 889 | E7: 67.76 | F7: 164 | G7: 190 | H7: 267 | I7: 222 | J7: 40 | K7: 6
A8: Pre Engineering | B8: Female | C8: 673 | D8: 567 | E8: 84.25 | F8: 153 | G8: 125 | H8: 161 | I8: 106 | J8: 19 | K8: 3
A9: Pre Engineering | B9: Total | C9: 1985 | D9: 1456 | E9: 73.35 | F9: 317 | G9: 315 | H9: 428 | I9: 328 | J9: 59 | K9: 9
A10: General Science | B10: Male | C10: 9564 | D10: 4989 | E10: 52.16 | F10: 377 | G10: 866 | H10: 1488 | I10: 1804 | J10: 454 | K10: 0
A11: General Science | B11: Female | C11: 8963 | D11: 6398 | E11: 71.38 | F11: 842 | G11: 1466 | H11: 2238 | I11: 1647 | J11: 205 | K11: 0
A12: General Science | B12: Total | C12: 18527 | D12: 11387 | E12: 61.46 | F12: 1219 | G12: 2332 | H12: 3726 | I12: 3451 | J12: 659 | K12: 0
A13: Humanities | B13: Male | C13: 10697 | D13: 3361 | E13: 31.42 | F13: 37 | G13: 325 | H13: 969 | I13: 1390 | J13: 617 | K13: 23
A14: Humanities | B14: Female | C14: 14127 | D14: 8281 | E14: 58.62 | F14: 346 | G14: 1713 | H14: 3223 | I14: 2475 | J14: 517 | K14: 7
A15: Humanities | B15: Total | C15: 24824 | D15: 11642 | E15: 46.9 | F15: 383 | G15: 2038 | H15: 4192 | I15: 3865 | J15: 1134 | K15: 30
... A22: Total | B22: Total | C22: 55727 | D22: 35404 | E22: 63.53 | F22: 5651 | G22: 7522 | H22: 11376 | I22: 8837 | J22: 1984 | K22: 34

Sheet BWP 2026 Subject Wise Pass %
A1: BISE Bahawalpur — Subject Wise Pass Percentage — Intermediate Part I & II Combined (First Annual) 2026
A2: Source: BISE Bahawalpur Result Gazette, Intermediate Part I & II Combined (First Annual) 2026 (supplied PDF). Pass % as published. All 76 subject entries.
A4: Year | B4: Subject Name | C4: Appeared | D4: Passed | E4: Pass %
A5: 2026 | B5: Arabic-I | C5: 127 | D5: 95 | E5: 74.8
A6: 2026 | B6: Arabic-II | C6: 1229 | D6: 1159 | E6: 94.3
A7: 2026 | B7: Banking | C7: 174 | D7: 174 | E7: 100
A8: 2026 | B8: Biology-I | C8: 3117 | D8: 1514 | E8: 48.57
A9: 2026 | B9: Biology-II | C9: 14294 | D9: 12623 | E9: 88.31
A10: 2026 | B10: Business Mathematics | C10: 24 | D10: 20 | E10: 83.33
A11: 2026 | B11: Business Stat | C11: 172 | D11: 160 | E11: 93.02
A12: 2026 | B12: Chemistry-I | C12: 4025 | D12: 1827 | E12: 45.39
A13: 2026 | B13: Chemistry-II | C13: 15996 | D13: 12948 | E13: 80.95
A14: 2026 | B14: Civics-I | C14: 1011 | D14: 873 | E14: 86.35
A15: 2026 | B15: Civics-II | C15: 4259 | D15: 3951 | E15: 92.77
A16: 2026 | B16: Commercial Geography | C16: 173 | D16: 172 | E16: 99.42
... A80: 2026 | B80: Urdu-II | C80: 52921 | D80: 51154 | E80: 96.66

Sheet BNU Overall Summary
A1: BOARD OF INTERMEDIATE AND SECONDARY EDUCATION, BANNU
A2: HSSC (11th & 12th) Annual-I Examination 2025 and 2026 — Result at a Glance. Part-II (2nd Year) is the final Class 12th result; Part-I (1st Year) candidates are promoted. Pass % calculated as Passed ÷ Appeared (gazette prints whole numbers: 2025 = 98, 86, 92; 2026 = 83, 82, no grand total printed).
A4: Year | B4: Part | C4: Appeared | D4: Passed | E4: Not Passed | F4: Pass % | G4: Published Pass %
A5: 2025 | B5: Part-I (1st Year, promoted) | C5: 16859 | D5: 16604 | E5: =C5-D5 -> 255 | F5: =ROUND(D5/C5*100,2) -> 98.49 | G5: 98
A6: 2025 | B6: Part-II (2nd Year, final) | C6: 18099 | D6: 15484 | E6: =C6-D6 -> 2615 | F6: =ROUND(D6/C6*100,2) -> 85.55 | G6: 86
A7: 2025 | B7: Grand Total (Part-I + Part-II) | C7: 34958 | D7: 32088 | E7: =C7-D7 -> 2870 | F7: =ROUND(D7/C7*100,2) -> 91.79 | G7: 92
A8: 2026 | B8: Part-I (1st Year) | C8: 17857 | D8: 14845 | E8: =C8-D8 -> 3012 | F8: =ROUND(D8/C8*100,2) -> 83.13 | G8: 83
A9: 2026 | B9: Part-II (2nd Year, final) | C9: 17771 | D9: 14484 | E9: =C9-D9 -> 3287 | F9: =ROUND(D9/C9*100,2) -> 81.5 | G9: 82
A10: 2026 | B10: Grand Total (Part-I + Part-II) | C10: 35628 | D10: 29329 | E10: =C10-D10 -> 6299 | F10: =ROUND(D10/C10*100,2) -> 82.32

Sheet BNU Group-wise
A1: Group-Wise Result — HSSC Annual-I 2025–2026 (1st Year and 2nd Year)
A2: Source: BISE Bannu, HSSC (11th & 12th) Annual-I Examination 2025 — Result at a Glance (gazette pp. v-vi). Pass % as published (whole numbers). Gazette inconsistencies kept as published: 2nd Year group Appeared adds to 18,056 vs printed Sub Total 18,099 (difference 43; Passed adds correctly to 15,484); 1st Year group Appeared adds to 16,853 vs printed Sub Total 16,859 (difference 6; Passed adds correctly to 16,604). Grand Total (34,958 / 32,088) = 1st Year + 2nd Year Sub Totals. 2026: gazette Result at a Glance (HSSC Part-I & Part-II Annual-I 2026); Pass % as published (whole numbers). Group Appeared and Passed add exactly to the printed Part-I (17,857 / 14,845) and Part-II (17,771 / 14,484) totals; the 2026 gazette prints no combined grand total, so 35,628 / 29,329 is the sum of the two. 2026 splits Pre-Computer and General Science (2025 combined them). Part-I Result Status not stated in the 2026 gazette.
A4: Year | B4: Part | C4: Group | D4: Row Type | E4: Appeared | F4: Passed | G4: Pass % (published) | H4: Pass % (calculated) | I4: Result Status
A5: 2025 | B5: Part-II (2nd Year) | C5: Pre Medical | D5: Detail | E5: 9582 | F5: 8548 | G5: 89 | H5: =ROUND(F5/E5*100,2) -> 89.21
A6: 2025 | B6: Part-II (2nd Year) | C6: Pre Engineering | D6: Detail | E6: 1602 | F6: 1393 | G6: 87 | H6: =ROUND(F6/E6*100,2) -> 86.95
A7: 2025 | B7: Part-II (2nd Year) | C7: General Science/Pre Computer | D7: Detail | E7: 2243 | F7: 1859 | G7: 83 | H7: =ROUND(F7/E7*100,2) -> 82.88
A8: 2025 | B8: Part-II (2nd Year) | C8: Humanities | D8: Detail | E8: 4629 | F8: 3684 | G8: 80 | H8: =ROUND(F8/E8*100,2) -> 79.59
A9: 2025 | B9: Part-II (2nd Year) | C9: Sub Total | D9: Sub Total | E9: 18099 | F9: 15484 | G9: 86 | H9: =ROUND(F9/E9*100,2) -> 85.55
A10: 2025 | B10: Part-I (1st Year) | C10: Pre Medical | D10: Detail | E10: 8202 | F10: 8064 | G10: 98 | H10: =ROUND(F10/E10*100,2) -> 98.32 | I10: Promoted
A11: 2025 | B11: Part-I (1st Year) | C11: Pre Engineering | D11: Detail | E11: 1502 | F11: 1493 | G11: 99 | H11: =ROUND(F11/E11*100,2) -> 99.4 | I11: Promoted
A12: 2025 | B12: Part-I (1st Year) | C12: General Science/Pre Computer | D12: Detail | E12: 2760 | F12: 2727 | G12: 99 | H12: =ROUND(F12/E12*100,2) -> 98.8 | I12: Promoted
